<?xml version="1.0" encoding="utf-8"?>
<robot xmlns:xacro="http://www.ros.org/wiki/xacro" name="panda">
  <xacro:arg name="arm_id_1" default="panda_0" />
  <xacro:arg name="arm_id_2" default="panda_1" />

  <xacro:include filename="$(find franka_description)/robots/panda_arm_no_limits.xacro"/>
  <xacro:include filename="$(find franka_description)/robots/hand.xacro"/>

  <!-- box shaped table as base for the 2 Pandas -->
  <link name="base">
    <visual>
      <origin xyz="0 0 -.095" rpy="0 0 0"/>
      <geometry>
        <cylinder length=".2" radius="2."/>
      </geometry>
      <material name="Tan">
        <color rgba=".4 .9 .4 1.0"/>
      </material>
    </visual>
    <collision>
      <origin xyz="0 0 -.09" rpy="0 0 0"/>
      <geometry>
        <cylinder length=".2" radius="2.5"/>
      </geometry>
    </collision>
  </link>

  <!-- right arm with gripper -->
  <xacro:panda_arm arm_id="$(arg arm_id_1)" connected_to="base"  xyz="-.65 0 0" safety_distance="0.03"/>
  <xacro:hand ns="$(arg arm_id_1)" rpy="0 0 ${-pi/4}" connected_to="$(arg arm_id_1)_link8" safety_distance="0.03"/>

  <!-- left arm with gripper -->
  <xacro:panda_arm arm_id="$(arg arm_id_2)" connected_to="base"  xyz=".65 0 0" safety_distance="0.03"/>
  <xacro:hand ns="$(arg arm_id_2)" rpy="0 0 ${-pi/4}" connected_to="$(arg arm_id_2)_link8" safety_distance="0.03"/>
  
  <!-- Tokens --> 
  <!-- blue -->
  <link name="blue_tok_0">
    <visual>
      <origin xyz="0 0 0." rpy="0 0 0"/>
      <geometry>
        <cylinder length=".03" radius=".04"/>
      </geometry>
      <material name="blue">
        <color rgba=".15 .5 .7 1.0"/>
      </material>
    </visual>
  </link>
  <joint name="blue_tok_0_link" type="floating">
    <parent link="base"/>
    <child link="blue_tok_0"/>
  </joint>
  
  <link name="blue_tok_1">
    <visual>
      <origin xyz="0 0 0." rpy="0 0 0"/>
      <geometry>
        <cylinder length=".03" radius=".04"/>
      </geometry>
      <material name="blue">
        <color rgba=".15 .5 .7 1.0"/>
      </material>
    </visual>
  </link>
  <joint name="blue_tok_1_link" type="floating">
    <parent link="base"/>
    <child link="blue_tok_1"/>
  </joint>
  
  <link name="blue_tok_2">
    <visual>
      <origin xyz="0 0 0." rpy="0 0 0"/>
      <geometry>
        <cylinder length=".03" radius=".04"/>
      </geometry>
      <material name="blue">
        <color rgba=".15 .5 .7 1.0"/>
      </material>
    </visual>
  </link>
  <joint name="blue_tok_2_link" type="floating">
    <parent link="base"/>
    <child link="blue_tok_2"/>
  </joint>
  
  <link name="blue_tok_3">
    <visual>
      <origin xyz="0 0 0." rpy="0 0 0"/>
      <geometry>
        <cylinder length=".03" radius=".04"/>
      </geometry>
      <material name="blue">
        <color rgba=".15 .5 .7 1.0"/>
      </material>
    </visual>
  </link>
  <joint name="blue_tok_3_link" type="floating">
    <parent link="base"/>
    <child link="blue_tok_3"/>
  </joint>
  
  <link name="blue_tok_4">
    <visual>
      <origin xyz="0 0 0." rpy="0 0 0"/>
      <geometry>
        <cylinder length=".03" radius=".04"/>
      </geometry>
      <material name="blue">
        <color rgba=".15 .5 .7 1.0"/>
      </material>
    </visual>
  </link>
  <joint name="blue_tok_4_link" type="floating">
    <parent link="base"/>
    <child link="blue_tok_4"/>
  </joint>
  
  <!-- red -->
  <link name="red_tok_0">
    <visual>
      <origin xyz="0 0 0." rpy="0 0 0"/>
      <geometry>
        <cylinder length=".03" radius=".04"/>
      </geometry>
      <material name="red">
        <color rgba=".7 .1 .1 1.0"/>
      </material>
    </visual>
  </link>
  <joint name="red_tok_0_link" type="floating">
    <parent link="base"/>
    <child link="red_tok_0"/>
  </joint>
  
  <link name="red_tok_1">
    <visual>
      <origin xyz="0 0 0." rpy="0 0 0"/>
      <geometry>
        <cylinder length=".03" radius=".04"/>
      </geometry>
      <material name="red">
        <color rgba=".7 .1 .1 1.0"/>
      </material>
    </visual>
  </link>
  <joint name="red_tok_1_link" type="floating">
    <parent link="base"/>
    <child link="red_tok_1"/>
  </joint>
  
  <link name="red_tok_2">
    <visual>
      <origin xyz="0 0 0." rpy="0 0 0"/>
      <geometry>
        <cylinder length=".03" radius=".04"/>
      </geometry>
      <material name="red">
        <color rgba=".7 .1 .1 1.0"/>
      </material>
    </visual>
  </link>
  <joint name="red_tok_2_link" type="floating">
    <parent link="base"/>
    <child link="red_tok_2"/>
  </joint>
  
  <link name="red_tok_3">
    <visual>
      <origin xyz="0 0 0." rpy="0 0 0"/>
      <geometry>
        <cylinder length=".03" radius=".04"/>
      </geometry>
      <material name="red">
        <color rgba=".7 .1 .1 1.0"/>
      </material>
    </visual>
  </link>
  <joint name="red_tok_3_link" type="floating">
    <parent link="base"/>
    <child link="red_tok_3"/>
  </joint>
  
  <link name="red_tok_4">
    <visual>
      <origin xyz="0 0 0." rpy="0 0 0"/>
      <geometry>
        <cylinder length=".03" radius=".04"/>
      </geometry>
      <material name="red">
        <color rgba=".7 .1 .1 1.0"/>
      </material>
    </visual>
  </link>
  <joint name="red_tok_4_link" type="floating">
    <parent link="base"/>
    <child link="red_tok_4"/>
  </joint>
  
  
  <!-- Bins -->
  <!-- Blue -->
  <link name="blue_bin">
    <visual>
      <origin xyz="0 0 0." rpy="0 0 0"/>
      <geometry>
        <cylinder length=".015" radius=".30"/>
      </geometry>
      <material name="light blue">
        <color rgba="0.2 .5 1 1.0"/>
      </material>
    </visual>
  </link>
  <joint name="blue_bin_link" type="floating">
    <parent link="base"/>
    <child link="blue_bin"/>
  </joint>
  
  <!-- Red -->
  <link name="red_bin">
    <visual>
      <origin xyz="0 0 0." rpy="0 0 0"/>
      <geometry>
        <cylinder length=".015" radius=".30"/>
      </geometry>
      <material name="light red">
        <color rgba="1 .2 .3 1.0"/>
      </material>
    </visual>
  </link>
  <joint name="red_bin_link" type="floating">
    <parent link="base"/>
    <child link="red_bin"/>
  </joint>
  
  
  
</robot>
